Traceback (most recent call last):
  File "/home/runner/.cache/pypoetry/virtualenvs/cb-events-GRcOqOou-py3.9/lib/python3.9/site-packages/jupyter_cache/executors/utils.py", line 58, in single_nb_execution
    executenb(
  File "/home/runner/.cache/pypoetry/virtualenvs/cb-events-GRcOqOou-py3.9/lib/python3.9/site-packages/nbclient/client.py", line 1314, in execute
    return NotebookClient(nb=nb, resources=resources, km=km, **kwargs).execute()
  File "/home/runner/.cache/pypoetry/virtualenvs/cb-events-GRcOqOou-py3.9/lib/python3.9/site-packages/jupyter_core/utils/__init__.py", line 165, in wrapped
    return loop.run_until_complete(inner)
  File "/opt/hostedtoolcache/Python/3.9.18/x64/lib/python3.9/asyncio/base_events.py", line 647, in run_until_complete
    return future.result()
  File "/home/runner/.cache/pypoetry/virtualenvs/cb-events-GRcOqOou-py3.9/lib/python3.9/site-packages/nbclient/client.py", line 709, in async_execute
    await self.async_execute_cell(
  File "/home/runner/.cache/pypoetry/virtualenvs/cb-events-GRcOqOou-py3.9/lib/python3.9/site-packages/nbclient/client.py", line 1062, in async_execute_cell
    await self._check_raise_for_error(cell, cell_index, exec_reply)
  File "/home/runner/.cache/pypoetry/virtualenvs/cb-events-GRcOqOou-py3.9/lib/python3.9/site-packages/nbclient/client.py", line 918, in _check_raise_for_error
    raise CellExecutionError.from_cell_and_msg(cell, exec_reply_content)
nbclient.exceptions.CellExecutionError: An error occurred while executing the following cell:
------------------
import asyncio

from cb_events.poller import CBAPIPoller, log_events


async def main() -> None:
    """Main entry point for the script."""
    url = "https://eventsapi.chaturbate.com/events/USER_NAME/API_KEY/"
    async with CBAPIPoller(url) as poller:
        await poller.fetch_events(event_callback=log_events)


if __name__ == "__main__":
    asyncio.run(main())

------------------


[0;31m---------------------------------------------------------------------------[0m
[0;31mRuntimeError[0m                              Traceback (most recent call last)
Cell [0;32mIn[1], line 14[0m
[1;32m     10[0m         [38;5;28;01mawait[39;00m poller[38;5;241m.[39mfetch_events(event_callback[38;5;241m=[39mlog_events)
[1;32m     13[0m [38;5;28;01mif[39;00m [38;5;18m__name__[39m [38;5;241m==[39m [38;5;124m"[39m[38;5;124m__main__[39m[38;5;124m"[39m:
[0;32m---> 14[0m     [43masyncio[49m[38;5;241;43m.[39;49m[43mrun[49m[43m([49m[43mmain[49m[43m([49m[43m)[49m[43m)[49m

File [0;32m/opt/hostedtoolcache/Python/3.9.18/x64/lib/python3.9/asyncio/runners.py:33[0m, in [0;36mrun[0;34m(main, debug)[0m
[1;32m      9[0m [38;5;250m[39m[38;5;124;03m"""Execute the coroutine and return the result.[39;00m
[1;32m     10[0m 
[1;32m     11[0m [38;5;124;03mThis function runs the passed coroutine, taking care of[39;00m
[0;32m   (...)[0m
[1;32m     30[0m [38;5;124;03m    asyncio.run(main())[39;00m
[1;32m     31[0m [38;5;124;03m"""[39;00m
[1;32m     32[0m [38;5;28;01mif[39;00m events[38;5;241m.[39m_get_running_loop() [38;5;129;01mis[39;00m [38;5;129;01mnot[39;00m [38;5;28;01mNone[39;00m:
[0;32m---> 33[0m     [38;5;28;01mraise[39;00m [38;5;167;01mRuntimeError[39;00m(
[1;32m     34[0m         [38;5;124m"[39m[38;5;124masyncio.run() cannot be called from a running event loop[39m[38;5;124m"[39m)
[1;32m     36[0m [38;5;28;01mif[39;00m [38;5;129;01mnot[39;00m coroutines[38;5;241m.[39miscoroutine(main):
[1;32m     37[0m     [38;5;28;01mraise[39;00m [38;5;167;01mValueError[39;00m([38;5;124m"[39m[38;5;124ma coroutine was expected, got [39m[38;5;132;01m{!r}[39;00m[38;5;124m"[39m[38;5;241m.[39mformat(main))

[0;31mRuntimeError[0m: asyncio.run() cannot be called from a running event loop

